[ 2023-11-02 18:15:46,916 ] 96 werkzeug - INFO - [31m[1mWARNING: This is a development server. Do not use it in a production deployment. Use a production WSGI server instead.[0m
 * Running on all addresses (0.0.0.0)
 * Running on http://127.0.0.1:5000
 * Running on http://192.168.0.122:5000
[ 2023-11-02 18:15:46,916 ] 96 werkzeug - INFO - [33mPress CTRL+C to quit[0m
[ 2023-11-02 18:16:25,972 ] 96 werkzeug - INFO - 127.0.0.1 - - [02/Nov/2023 18:16:25] "GET / HTTP/1.1" 200 -
[ 2023-11-02 18:16:26,129 ] 96 werkzeug - INFO - 127.0.0.1 - - [02/Nov/2023 18:16:26] "[33mGET /favicon.ico HTTP/1.1[0m" 404 -
[ 2023-11-02 18:16:33,403 ] 96 werkzeug - INFO - 127.0.0.1 - - [02/Nov/2023 18:16:33] "GET /predict HTTP/1.1" 200 -
[ 2023-11-02 18:17:05,693 ] 825 app - ERROR - Exception on /predict [POST]
Traceback (most recent call last):
  File "/Users/yahyamohnd/Desktop/MLOps_Project/mlproject/src/utils.py", line 58, in load_object
    with open(file_path, "rb") as file_obj:
FileNotFoundError: [Errno 2] No such file or directory: 'artifacts/preprocessor.pkl'

During handling of the above exception, another exception occurred:

Traceback (most recent call last):
  File "/Users/yahyamohnd/Desktop/MLOps_Project/mlproject/src/pipline/predict_pipeline.py", line 18, in predict
    preprocessor=load_object(file_path=preprocessor_path)
  File "/Users/yahyamohnd/Desktop/MLOps_Project/mlproject/src/utils.py", line 62, in load_object
    raise CustomException(e, sys)
src.exception.CustomException: Error occured in python script name [/Users/yahyamohnd/Desktop/MLOps_Project/mlproject/src/utils.py] line number [58] error message[[Errno 2] No such file or directory: 'artifacts/preprocessor.pkl']

During handling of the above exception, another exception occurred:

Traceback (most recent call last):
  File "/Users/yahyamohnd/Desktop/MLOps_Project/mlproject/mlproject/lib/python3.10/site-packages/flask/app.py", line 1455, in wsgi_app
    response = self.full_dispatch_request()
  File "/Users/yahyamohnd/Desktop/MLOps_Project/mlproject/mlproject/lib/python3.10/site-packages/flask/app.py", line 869, in full_dispatch_request
    rv = self.handle_user_exception(e)
  File "/Users/yahyamohnd/Desktop/MLOps_Project/mlproject/mlproject/lib/python3.10/site-packages/flask/app.py", line 867, in full_dispatch_request
    rv = self.dispatch_request()
  File "/Users/yahyamohnd/Desktop/MLOps_Project/mlproject/mlproject/lib/python3.10/site-packages/flask/app.py", line 852, in dispatch_request
    return self.ensure_sync(self.view_functions[rule.endpoint])(**view_args)
  File "/Users/yahyamohnd/Desktop/MLOps_Project/mlproject/app.py", line 36, in predict_datapoint
    results=predict_pipeline.predict(pred_df)
  File "/Users/yahyamohnd/Desktop/MLOps_Project/mlproject/src/pipline/predict_pipeline.py", line 25, in predict
    raise CustomException(e,sys)
src.exception.CustomException: Error occured in python script name [/Users/yahyamohnd/Desktop/MLOps_Project/mlproject/src/pipline/predict_pipeline.py] line number [18] error message[Error occured in python script name [/Users/yahyamohnd/Desktop/MLOps_Project/mlproject/src/utils.py] line number [58] error message[[Errno 2] No such file or directory: 'artifacts/preprocessor.pkl']]
[ 2023-11-02 18:17:05,694 ] 96 werkzeug - INFO - 127.0.0.1 - - [02/Nov/2023 18:17:05] "[35m[1mPOST /predict HTTP/1.1[0m" 500 -
[ 2023-11-02 18:17:43,013 ] 825 app - ERROR - Exception on /predict [POST]
Traceback (most recent call last):
  File "/Users/yahyamohnd/Desktop/MLOps_Project/mlproject/src/utils.py", line 58, in load_object
    with open(file_path, "rb") as file_obj:
FileNotFoundError: [Errno 2] No such file or directory: 'artifacts/preprocessor.pkl'

During handling of the above exception, another exception occurred:

Traceback (most recent call last):
  File "/Users/yahyamohnd/Desktop/MLOps_Project/mlproject/src/pipline/predict_pipeline.py", line 18, in predict
    preprocessor=load_object(file_path=preprocessor_path)
  File "/Users/yahyamohnd/Desktop/MLOps_Project/mlproject/src/utils.py", line 62, in load_object
    raise CustomException(e, sys)
src.exception.CustomException: Error occured in python script name [/Users/yahyamohnd/Desktop/MLOps_Project/mlproject/src/utils.py] line number [58] error message[[Errno 2] No such file or directory: 'artifacts/preprocessor.pkl']

During handling of the above exception, another exception occurred:

Traceback (most recent call last):
  File "/Users/yahyamohnd/Desktop/MLOps_Project/mlproject/mlproject/lib/python3.10/site-packages/flask/app.py", line 1455, in wsgi_app
    response = self.full_dispatch_request()
  File "/Users/yahyamohnd/Desktop/MLOps_Project/mlproject/mlproject/lib/python3.10/site-packages/flask/app.py", line 869, in full_dispatch_request
    rv = self.handle_user_exception(e)
  File "/Users/yahyamohnd/Desktop/MLOps_Project/mlproject/mlproject/lib/python3.10/site-packages/flask/app.py", line 867, in full_dispatch_request
    rv = self.dispatch_request()
  File "/Users/yahyamohnd/Desktop/MLOps_Project/mlproject/mlproject/lib/python3.10/site-packages/flask/app.py", line 852, in dispatch_request
    return self.ensure_sync(self.view_functions[rule.endpoint])(**view_args)
  File "/Users/yahyamohnd/Desktop/MLOps_Project/mlproject/app.py", line 36, in predict_datapoint
    results=predict_pipeline.predict(pred_df)
  File "/Users/yahyamohnd/Desktop/MLOps_Project/mlproject/src/pipline/predict_pipeline.py", line 25, in predict
    raise CustomException(e,sys)
src.exception.CustomException: Error occured in python script name [/Users/yahyamohnd/Desktop/MLOps_Project/mlproject/src/pipline/predict_pipeline.py] line number [18] error message[Error occured in python script name [/Users/yahyamohnd/Desktop/MLOps_Project/mlproject/src/utils.py] line number [58] error message[[Errno 2] No such file or directory: 'artifacts/preprocessor.pkl']]
[ 2023-11-02 18:17:43,015 ] 96 werkzeug - INFO - 127.0.0.1 - - [02/Nov/2023 18:17:43] "[35m[1mPOST /predict HTTP/1.1[0m" 500 -
[ 2023-11-02 18:17:50,392 ] 825 app - ERROR - Exception on /predict [POST]
Traceback (most recent call last):
  File "/Users/yahyamohnd/Desktop/MLOps_Project/mlproject/src/utils.py", line 58, in load_object
    with open(file_path, "rb") as file_obj:
FileNotFoundError: [Errno 2] No such file or directory: 'artifacts/preprocessor.pkl'

During handling of the above exception, another exception occurred:

Traceback (most recent call last):
  File "/Users/yahyamohnd/Desktop/MLOps_Project/mlproject/src/pipline/predict_pipeline.py", line 18, in predict
    preprocessor=load_object(file_path=preprocessor_path)
  File "/Users/yahyamohnd/Desktop/MLOps_Project/mlproject/src/utils.py", line 62, in load_object
    raise CustomException(e, sys)
src.exception.CustomException: Error occured in python script name [/Users/yahyamohnd/Desktop/MLOps_Project/mlproject/src/utils.py] line number [58] error message[[Errno 2] No such file or directory: 'artifacts/preprocessor.pkl']

During handling of the above exception, another exception occurred:

Traceback (most recent call last):
  File "/Users/yahyamohnd/Desktop/MLOps_Project/mlproject/mlproject/lib/python3.10/site-packages/flask/app.py", line 1455, in wsgi_app
    response = self.full_dispatch_request()
  File "/Users/yahyamohnd/Desktop/MLOps_Project/mlproject/mlproject/lib/python3.10/site-packages/flask/app.py", line 869, in full_dispatch_request
    rv = self.handle_user_exception(e)
  File "/Users/yahyamohnd/Desktop/MLOps_Project/mlproject/mlproject/lib/python3.10/site-packages/flask/app.py", line 867, in full_dispatch_request
    rv = self.dispatch_request()
  File "/Users/yahyamohnd/Desktop/MLOps_Project/mlproject/mlproject/lib/python3.10/site-packages/flask/app.py", line 852, in dispatch_request
    return self.ensure_sync(self.view_functions[rule.endpoint])(**view_args)
  File "/Users/yahyamohnd/Desktop/MLOps_Project/mlproject/app.py", line 36, in predict_datapoint
    results=predict_pipeline.predict(pred_df)
  File "/Users/yahyamohnd/Desktop/MLOps_Project/mlproject/src/pipline/predict_pipeline.py", line 25, in predict
    raise CustomException(e,sys)
src.exception.CustomException: Error occured in python script name [/Users/yahyamohnd/Desktop/MLOps_Project/mlproject/src/pipline/predict_pipeline.py] line number [18] error message[Error occured in python script name [/Users/yahyamohnd/Desktop/MLOps_Project/mlproject/src/utils.py] line number [58] error message[[Errno 2] No such file or directory: 'artifacts/preprocessor.pkl']]
[ 2023-11-02 18:17:50,393 ] 96 werkzeug - INFO - 127.0.0.1 - - [02/Nov/2023 18:17:50] "[35m[1mPOST /predict HTTP/1.1[0m" 500 -
